Workbook

Sheet Feuil1
A1: Date | B1: Comptes | C1: Montant
A2: 45657 | B2: 4500 | C2: 800000
A3: 45657 | B3: 5010 | C3: 100000
A4: 45657 | B4: 5100 | C4: 600000
A5: 45657 | B5: 5150 | C5: 60000
A6: 45657 | B6: 5300 | C6: 50150
A7: 45657 | B7: 5305 | C7: 30000
A8: 45657 | B8: 5420 | C8: 12000
A9: 45657 | B9: 5740 | C9: 7350
A10: 45657 | B10: 5725 | C10: 700
A11: 45657 | B11: 5726 | C11: 100
A12: 45657 | B12: 5650 | C12: 500
A13: 45657 | B13: 5345 | C13: 4000
... A18: 45657 | B18: 3300 | C18: 40000

Sheet Feuil2
A1: Date | B1: Comptes | C1: Montant
A2: 45657 | B2: 4120 | C2: 29000
A3: 45657 | B3: 5300 | C3: 8664
A4: 45657 | B4: 5420 | C4: 2000
A5: 45657 | B5: 5740 | C5: 818
A6: 45657 | B6: 5500 | C6: 2272
A7: 45657 | B7: 5640 | C7: 1636
A8: 45657 | B8: 3100 | C8: 60000
A9: 45657 | B9: 3200 | C9: 5000
A10: 45657 | B10: 3300 | C10: 3000
A11: 45657 | B11: 1010 | C11: 2000
A12: 45657 | B12: 1190 | C12: 3250
A13: 45657 | B13: 1400 | C13: 32860
... A18: 45657 | B18: 2900 | C18: 340000

Sheet Feuil3
A1: Date | B1: Comptes | C1: Montant
A2: 45383 | B2: 3200 | C2: 23857.95
A3: 45383 | B3: 1010 | C3: 23857.95
A4: 45383 | B4: 3200 | C4: 59273.46
A5: 45383 | B5: 1050 | C5: 59273.46
A6: 45383 | B6: 3200 | C6: 5199.89
A7: 45383 | B7: 1100 | C7: 5199.89
A8: 45383 | B8: 4160 | C8: 2120.71
A9: 45383 | B9: 1010 | C9: 2120.71
A10: 45384 | B10: 4160 | C10: 212
A11: 45384 | B11: 1010 | C11: 212
A12: 45390 | B12: 4160 | C12: 212
A13: 45390 | B13: 1010 | C13: 212
... A199: 45600 | B199: 1010 | C199: 212

Sheet Budget
A1: Date | B1: Comptes | C1: Montant
A2: 45383 | B2: 3200 | C2: 23857.95
A3: 45383 | B3: 1010 | C3: 23857.95
A4: 45383 | B4: 3200 | C4: 59273.46
A5: 45383 | B5: 1050 | C5: 59273.46
A6: 45383 | B6: 3200 | C6: 5199.89
A7: 45383 | B7: 1100 | C7: 5199.89
A8: 45383 | B8: 4160 | C8: 2120.71
A9: 45383 | B9: 1010 | C9: 2120.71
A10: 45383 | B10: 4160 | C10: 212
A11: 45383 | B11: 1010 | C11: 212
A12: 45383 | B12: 4160 | C12: 212
A13: 45383 | B13: 1010 | C13: 212
... A187: 45418 | B187: 5660 | C187: 1200

Sheet Feuil5
A1: Date | B1: Comptes | C1: Montant | D1: Description | E1: Explication
A2: 45658 | B2: 3200 | C2: 6201.05 | D2: =VLOOKUP(B2,'Plan Comptable'!A:B,2,FALSE) -> Apport
A3: 45658 | B3: 1010 | C3: 6201.05 | D3: =VLOOKUP(B3,'Plan Comptable'!A:B,2,FALSE) -> 0033830-EOP Épargne avec opérations (C)
A4: 45658 | B4: 3200 | C4: 6.15 | D4: =VLOOKUP(B4,'Plan Comptable'!A:B,2,FALSE) -> Apport
A5: 45658 | B5: 1100 | C5: 6.15 | D5: =VLOOKUP(B5,'Plan Comptable'!A:B,2,FALSE) -> 0033830-ET1 Compte avantage entreprise
A6: 45658 | B6: 3200 | C6: 95502.85 | D6: =VLOOKUP(B6,'Plan Comptable'!A:B,2,FALSE) -> Apport
A7: 45658 | B7: 1010 | C7: 95502.85 | D7: =VLOOKUP(B7,'Plan Comptable'!A:B,2,FALSE) -> 0033830-EOP Épargne avec opérations (C)
A8: 45663 | B8: 4160 | C8: 2332.73 | D8: =VLOOKUP(B8,'Plan Comptable'!A:B,2,FALSE) -> Cotisation
A9: 45663 | B9: 1010 | C9: 2332.73 | D9: =VLOOKUP(B9,'Plan Comptable'!A:B,2,FALSE) -> 0033830-EOP Épargne avec opérations (C)
A10: 45664 | B10: 4160 | C10: -212.11 | D10: =VLOOKUP(B10,'Plan Comptable'!A:B,2,FALSE) -> Cotisation | E10: Rebond Olivier
A11: 45664 | B11: 1010 | C11: -212.11 | D11: =VLOOKUP(B11,'Plan Comptable'!A:B,2,FALSE) -> 0033830-EOP Épargne avec opérations (C) | E11: Rebond Olivier
A12: 45670 | B12: 1010 | C12: -12.08 | D12: =VLOOKUP(B12,'Plan Comptable'!A:B,2,FALSE) -> 0033830-EOP Épargne avec opérations (C)
A13: 45670 | B13: 5726 | C13: 12.08 | D13: =VLOOKUP(B13,'Plan Comptable'!A:B,2,FALSE) -> Trés. / comptabilité
A14: 45680 | B14: 1010 | C14: -1450 | D14: =VLOOKUP(B14,'Plan Comptable'!A:B,2,FALSE) -> 0033830-EOP Épargne avec opérations (C) | E14: Roger St-Michel
A15: 45680 | B15: 5725 | C15: 1450 | D15: =VLOOKUP(B15,'Plan Comptable'!A:B,2,FALSE) -> Dépenses de gestion | E15: Roger St-Michel
A16: 45680 | B16: 1010 | C16: -1006.03 | D16: =VLOOKUP(B16,'Plan Comptable'!A:B,2,FALSE) -> 0033830-EOP Épargne avec opérations (C)
A17: 45680 | B17: 5700 | C17: 1006.03 | D17: =VLOOKUP(B17,'Plan Comptable'!A:B,2,FALSE) -> Déneigement + à la main
A18: 45688 | B18: 1010 | C18: -5.95 | D18: =VLOOKUP(B18,'Plan Comptable'!A:B,2,FALSE) -> 0033830-EOP Épargne avec opérations (C)
A19: 45688 | B19: 5720 | C19: 5.95 | D19: =VLOOKUP(B19,'Plan Comptable'!A:B,2,FALSE) -> Frais de banque
A20: 45688 | B20: 1010 | C20: -5 | D20: =VLOOKUP(B20,'Plan Comptable'!A:B,2,FALSE) -> 0033830-EOP Épargne avec opérations (C)
A21: 45688 | B21: 5720 | C21: 5 | D21: =VLOOKUP(B21,'Plan Comptable'!A:B,2,FALSE) -> Frais de banque
A22: 45688 | B22: 4290 | C22: 0.01 | D22: =VLOOKUP(B22,'Plan Comptable'!A:B,2,FALSE) -> Produits d'intérêts
A23: 45688 | B23: 1100 | C23: 0.01 | D23: =VLOOKUP(B23,'Plan Comptable'!A:B,2,FALSE) -> 0033830-ET1 Compte avantage entreprise
A24: 45688 | B24: 4290 | C24: 201.71 | D24: =VLOOKUP(B24,'Plan Comptable'!A:B,2,FALSE) -> Produits d'intérêts
A25: 45688 | B25: 1105 | C25: 201.71 | D25: =VLOOKUP(B25,'Plan Comptable'!A:B,2,FALSE) -> 0033830-ET2 Compte avantage entreprise
A26: 45691 | B26: 4160 | C26: 212 | D26: =VLOOKUP(B26,'Plan Comptable'!A:B,2,FALSE) -> Cotisation
A27: 45691 | B27: 1010 | C27: 212 | D27: =VLOOKUP(B27,'Plan Comptable'!A:B,2,FALSE) -> 0033830-EOP Épargne avec opérations (C)
... A57: 45748 | B57: 1010 | C57: 2332.73 | D57: =VLOOKUP(B57,'Plan Comptable'!A:B,2,FALSE) -> 0033830-EOP Épargne avec opérations (C)
A58: 45749 | B58: 1010 | C58: -280 | D58: =VLOOKUP(B58,'Plan Comptable'!A:B,2,FALSE) -> 0033830-EOP Épargne avec opérations (C) | E58: Roger St-Michel
A59: 45749 | B59: 5725 | C59: 280 | D59: =VLOOKUP(B59,'Plan Comptable'!A:B,2,FALSE) -> Dépenses de gestion | E59: Roger St-Michel
A60: 45749 | B60: 1010 | C60: -420 | D60: =VLOOKUP(B60,'Plan Comptable'!A:B,2,FALSE) -> 0033830-EOP Épargne avec opérations (C) | E60: Thalia Beaudry
A61: 45749 | B61: 5725 | C61: 420 | D61: =VLOOKUP(B61,'Plan Comptable'!A:B,2,FALSE) -> Dépenses de gestion | E61: Thalia Beaudry
A62: 45754 | B62: 1010 | C62: -360 | D62: =VLOOKUP(B62,'Plan Comptable'!A:B,2,FALSE) -> 0033830-EOP Épargne avec opérations (C) | E62: Jean-Maurice Breton
A63: 45754 | B63: 5725 | C63: 360 | D63: =VLOOKUP(B63,'Plan Comptable'!A:B,2,FALSE) -> Dépenses de gestion | E63: Jean-Maurice Breton
A64: 45758 | B64: 1010 | C64: -63.26 | D64: =VLOOKUP(B64,'Plan Comptable'!A:B,2,FALSE) -> 0033830-EOP Épargne avec opérations (C) | E64: Hydro-québec
A65: 45758 | B65: 5680 | C65: 63.26 | D65: =VLOOKUP(B65,'Plan Comptable'!A:B,2,FALSE) -> Entretien & rép. ext. | E65: Hydro-québec
A66: 45761 | B66: 1010 | C66: -12.08 | D66: =VLOOKUP(B66,'Plan Comptable'!A:B,2,FALSE) -> 0033830-EOP Épargne avec opérations (C)
A67: 45761 | B67: 5726 | C67: 12.08 | D67: =VLOOKUP(B67,'Plan Comptable'!A:B,2,FALSE) -> Trés. / comptabilité
A68: 45775 | B68: 1010 | C68: -1014.08 | D68: =VLOOKUP(B68,'Plan Comptable'!A:B,2,FALSE) -> 0033830-EOP Épargne avec opérations (C) | E68: Tondeuse
A69: 45775 | B69: 5680 | C69: 1014.08 | D69: =VLOOKUP(B69,'Plan Comptable'!A:B,2,FALSE) -> Entretien & rép. ext. | E69: Tondeuse
...

Sheet Plan Comptable
A1: NO | B1: COMPTE
A2: 1010 | B2: 0033830-EOP Épargne avec opérations (C)
A3: 1050 | B3: 0033830-ES1 Épargne stable à intérêt quotidien
A4: 1100 | B4: 0033830-ET1 Compte avantage entreprise
A5: 1105 | B5: 0033830-ET2 Compte avantage entreprise
A6: 1110 | B6: Intérêts à recevoir
A7: 4160 | B7: Cotisation
A8: 4290 | B8: Produits d'intérêts
A9: 5650 | B9: Assurances
A10: 5660 | B10: Électricité
A11: 5670 | B11: Entretien ménager
A12: 5680 | B12: Entretien & rép. ext.
A13: 5690 | B13: Entretien & rép. bâtiment
... A23: 3200 | B23: Apport
